Workbook
Name lst_Acao: LISTAS!$AP$2:$AP$32
Name lst_Analistas: LISTAS!$BB$2:$BB$24
Name lst_Apolices: APOLICES!$A$2:$A$31
Name lst_CanalBR: LISTAS!$U$2:$U$25
Name lst_CanalVizinho: LISTAS!$V$2:$V$25
Name lst_CategMerc: LISTAS!$AZ$2:$AZ$31
Name lst_CausaRecusa: LISTAS!$AV$2:$AV$28
Name lst_Checklists: CHECKLISTS!$A$2:$A$401
Name lst_Clientes: CLIENTES!$B$2:$B$101
Name lst_CNHCat: LISTAS!$AD$2:$AD$24
Name lst_Comunicacao: LISTAS!$G$2:$G$26
Name lst_Criticidade: LISTAS!$Y$2:$Y$25
Name lst_DocAverb: LISTAS!$R$2:$R$26
Name lst_DocViagem: LISTAS!$AC$2:$AC$24
Name lst_Entidade: LISTAS!$J$2:$J$24
Name lst_Fabricante: LISTAS!$E$2:$E$29
Name lst_Fonte: LISTAS!$AY$2:$AY$29
Name lst_FuncaoRastr: LISTAS!$F$2:$F$28
Name lst_GR: LISTAS!$AG$2:$AG$31
Name lst_Macro: LISTAS!$AX$2:$AX$32
Name lst_MeioContato: LISTAS!$AA$2:$AA$25
Name lst_Moeda: LISTAS!$L$2:$L$23
Name lst_Motoristas: MOTORISTAS!$A$2:$A$401
Name lst_NC_PGR: LISTAS!$AR$2:$AR$34
Name lst_Pais: LISTAS!$T$2:$T$28
Name lst_Permissoes: LISTAS!$P$2:$P$23
Name lst_Placas: VEICULOS!$A$2:$A$401
Name lst_PostoFronteira: LISTAS!$AM$2:$AM$38
Name lst_Ramo: LISTAS!$AS$2:$AS$30
Name lst_Recinto: LISTAS!$X$2:$X$25
Name lst_ResItem: LISTAS!$N$2:$N$26
Name lst_ResultConsulta: LISTAS!$AF$2:$AF$30
Name lst_Seguradora: LISTAS!$AH$2:$AH$23
Name lst_SenhaValidada: LISTAS!$Z$2:$Z$25
Name lst_Sentido: LISTAS!$W$2:$W$25
Name lst_SituacaoVeic: LISTAS!$AB$2:$AB$26
Name lst_SMPs: SMP!$A$2:$A$401
Name lst_SN: LISTAS!$A$2:$A$25
Name lst_StatusAverb: LISTAS!$AK$2:$AK$30
Name lst_StatusEquip: LISTAS!$H$2:$H$27
Name lst_StatusEsp: LISTAS!$AJ$2:$AJ$28
Name lst_StatusFront: LISTAS!$AN$2:$AN$32
Name lst_StatusOcorr: LISTAS!$AQ$2:$AQ$28
Name lst_StatusOS: LISTAS!$BA$2:$BA$24
Name lst_StatusSinistro: LISTAS!$AU$2:$AU$27
Name lst_StatusSMP: LISTAS!$AI$2:$AI$31
Name lst_StatusViagem: LISTAS!$AL$2:$AL$44
Name lst_TipoAlvo: LISTAS!$I$2:$I$25
Name lst_TipoChecklist: LISTAS!$M$2:$M$26
Name lst_TipoDestinoEsp: LISTAS!$O$2:$O$27
Name lst_TipoEvento: LISTAS!$AO$2:$AO$48
Name lst_TipoPonto: LISTAS!$AE$2:$AE$26
Name lst_TipoProf: LISTAS!$K$2:$K$24
Name lst_TipoRegistro: LISTAS!$AW$2:$AW$26
Name lst_TipoSinistro: LISTAS!$AT$2:$AT$31
Name lst_TipoUnidade: LISTAS!$C$2:$C$24
Name lst_TipoVeiculo: LISTAS!$D$2:$D$30
Name lst_ViaAverb: LISTAS!$S$2:$S$25
Name lst_Viagens: FOLLOWUP!$A$2:$A$401
Name lst_Vigencia: LISTAS!$Q$2:$Q$23

Sheet LEIA_ME
A1: MEGA PLANILHA DE CONTROLE GR - RIGABRAS
A2: Gerado em 25/09/2026. Compatível com Excel 2007 ou superior. Todos os dados de exemplo são FICTÍCIOS (inclusive nomes de gerenciadora de risco e seguradora, marcados como 'A DEFINIR') - substitua pelos dados reais assim que confirmados. COMO USAR NO DIA A DIA (rotina sugerida): D-1 (véspera da viagem): cadastrar a viagem em FOLLOWUP (placa, carreta, motorista, cliente, carga, rota, data de carregamento); conferir MOTORISTAS e CONSULTAS (GR e seguradora); abrir/atualizar CHECKLISTS; solicitar e confirmar ESPELHAMENTOS. D0 (dia do carregamento): registrar carregamento real em FOLLOWUP; abrir a SMP; confirmar averbação em AVERBACOES; conferir a coluna 'APTO A SAIR' antes de liberar a viagem. Em viagem: atualizar Status em FOLLOWUP a cada mudança relevante; lançar POSICOES/macros conforme chegam do rastreamento; abrir OCORRENCIAS para qualquer alerta; preencher FRONTEIRA ao chegar/sair da fronteira. Fim de viagem: registrar chegada e descarga; encerrar SMP e ESPELHAMENTOS; se houver sinistro, abrir em SINISTROS vinculado à OCORRENCIA. ONDE DIGITAR X ONDE NÃO DIGITAR: Colunas com fundo cinza-claro (#F2F2F2) na aba FOLLOWUP e nas demais tabelas são FÓRMULAS - não digite nelas, apenas leia o resultado. As demais colunas (fundo branco) são de preenchimento manual. Sempre que possível, use as listas suspensas (setas ao lado da célula) em vez de digitar livremente, para manter o vocabulário controlado que alimenta o bot. CORES (formatação condicional): Vermelho = pendência/vencido/crítico. Laranja = atenção/perto de vencer. Amarelo = aviso leve. Verde = OK/aprovado/vigente. Roxo = exceção que requer aprovação especial (ex.: carga acima do LMG sem aprovação da seguradora). Cinza = linha desatualizada. ABAS DA PLANILHA: FOLLOWUP é a aba principal (uma linha por viagem) e a principal fonte de dados para o bot. PAINEL traz os indicadores consolidados. PERFIL_EMPRESA reúne o que se sabe sobre a Rigabras, com fontes. DICIONARIO_BOT e FAQ_BOT documentam, para quem for integrar o bot, o significado de cada coluna e modelos de resposta para as perguntas mais comuns. As demais abas são cadastros de apoio (motoristas, veículos, rastreadores) ou tabelas transacionais (checklists, SMP, averbações, ocorrências, sinistros, fronteira, posições). PARAMETROS reúne os prazos e limites usados pelas fórmulas (validade de consulta, antecedência de SMP e espelhamento, limites de alerta de sinal e fronteira etc.) - ajuste-os ali, sem precisar mexer nas fórmulas. LISTAS guarda as listas suspensas usadas em toda a planilha. LIMITAÇÕES DESTA VERSÃO (documentadas para o analista revisar): - Os valores de PGR_REGRAS e APOLICES são EXEMPLOS de mercado, não confirmados para a Rigabras. - Os nomes de GR e seguradora aparecem como 'A DEFINIR' - a pesquisa pública não encontrou essa informação. - A aba DADOS_RESTRITOS (dados pessoais sensíveis: CPF, RG, passaporte etc.) foi propositalmente OMITIDA desta primeira versão por tratar-se de dado sensível (LGPD); se for necessária, crie-a separadamente, oculta e protegida por senha, e NUNCA a exponha ao bot. - Verifique periodicamente (recálculo completo do Excel: Fórmulas > Calcular Agora, ou F9) se todas as fórmulas atualizaram - datas como HOJE() e AGORA() mudam a cada abertura do arquivo.

Sheet PAINEL
A1: PAINEL GR - RIGABRAS
A2: Atualizado em | B2: =NOW() -> 46290.817
A3: Mês de referência | B3: =P_MES_REF -> 46266
A5: Operação agora
A6: Veículos em viagem | B6: =COUNTIF(FOLLOWUP!$BO$2:$BO$2000,"Sim") -> 1
A7: Em fronteira | B7: =COUNTIF(FOLLOWUP!$BP$2:$BP$2000,"Sim") -> 1
A8: Retidos (status 14) | B8: =COUNTIF(FOLLOWUP!$BM$2:$BM$2000,14) -> 0
A9: Carregaram hoje | B9: =COUNTIFS(FOLLOWUP!$AP$2:$AP$2000,">="&TODAY(),FOLLOWUP!$AP$2:$AP$2000,"<"&(TODAY()+1)) -> 1
A10: Chegaram hoje | B10: =COUNTIFS(FOLLOWUP!$BR$2:$BR$2000,">="&TODAY(),FOLLOWUP!$BR$2:$BR$2000,"<"&(TODAY()+1)) -> 0
A11: Programadas p/ amanhã | B11: =COUNTIFS(FOLLOWUP!$AO$2:$AO$2000,TODAY()+1) -> 1
A12: BLOQUEADAS com status 06-07 | B12: =COUNTIFS(FOLLOWUP!$CD$2:$CD$2000,"BLOQUEADO",FOLLOWUP!$BM$2:$BM$2000,">=6",FOLLOWUP!$BM$2:$BM$2000,"<=7") -> 1
A13: Saídas irregulares (meta 0) | B13: =COUNTIF(FOLLOWUP!$CH$2:$CH$2000,"Sim") -> 0
A14: Sem sinal > 1h | B14: =COUNTIFS(FOLLOWUP!$BW$2:$BW$2000,">="&P_SINAL_ALERTA) -> 3
A15: Sem sinal > 4h | B15: =COUNTIFS(FOLLOWUP!$BW$2:$BW$2000,">="&P_SINAL_CRIT) -> 3
A16: Ocorrências abertas | B16: =COUNTIF(OCORRENCIAS!$Z$2:$Z$2000,"Sim") -> 1
A17: Ocorrências críticas abertas | B17: =COUNTIFS(OCORRENCIAS!$Z$2:$Z$2000,"Sim",OCORRENCIAS!$G$2:$G$2000,"Crítica") -> 0
A18: Linhas desatualizadas | B18: =COUNTIF(FOLLOWUP!$CP$2:$CP$2000,"Sim") -> 2
A20: Cadastro
A21: Motoristas ativos | B21: =COUNTIF(MOTORISTAS!$AB$2:$AB$2000,"Sim") -> 5
A22: % com GR e seguradora válidas | B22: =IFERROR(COUNTIFS(MOTORISTAS!$AB$2:$AB$2000,"Sim",MOTORISTAS!$W$2:$W$2000,"Sim",MOTORISTAS!$X$2:$X$2000,"Sim")/COUNTIF(MOTORISTAS!$AB$2:$AB$2000,"Sim"),0) -> 0.6
A23: Motoristas inaptos ativos | B23: =COUNTIFS(MOTORISTAS!$AA$2:$AA$2000,"Inapto",MOTORISTAS!$AB$2:$AB$2000,"Sim") -> 2
A24: Consultas a vencer (<=15 dias) | B24: =COUNTIF(CONSULTAS!$R$2:$R$2000,"A vencer") -> 1
A25: % perfis divergentes/insuficientes | B25: =IFERROR((COUNTIF(CONSULTAS!$M$2:$M$2000,"Divergente")+COUNTIF(CONSULTAS!$M$2:$M$2000,"Insuficiente"))/COUNTA(CONSULTAS!$A$2:$A$2000),0) -> 0
A26: Apólices vigentes | B26: =COUNTIF(APOLICES!$I$2:$I$31,"Vigente") -> 4
A27: Apólices a vencer | B27: =COUNTIF(APOLICES!$I$2:$I$31,"A vencer") -> 1
A28: Apólices vencidas | B28: =COUNTIF(APOLICES!$I$2:$I$31,"Vencida") -> 0
A30: Conformidade no mês (Vm = viagens carregadas no mês de referência)
A31: Vm - viagens carregadas no mês | B31: =COUNTIFS(FOLLOWUP!$AP$2:$AP$2000,">="&$B$3,FOLLOWUP!$AP$2:$AP$2000,"<"&DATE(YEAR($B$3),MONTH($B$3)+1,1)) -> 4
A32: % APTO na saída | B32: =IFERROR(COUNTIFS(FOLLOWUP!$CD$2:$CD$2000,"APTO",FOLLOWUP!$AP$2:$AP$2000,">="&$B$3,FOLLOWUP!$AP$2:$AP$2000,"<"&DATE(YEAR($B$3),MONTH($B$3)+1,1))/$B$31,0) -> 0.5
A33: % SMP liberada antes da saída | B33: =IFERROR(COUNTIFS(SMP!$X$2:$X$2000,"Sim",SMP!$G$2:$G$2000,">="&$B$3)/$B$31,0) -> 0.75
A34: Tempo médio de liberação SMP (min) | B34: =IFERROR(AVERAGEIFS(SMP!$W$2:$W$2000,SMP!$G$2:$G$2000,">="&$B$3),0) -> 28
A35: % checklist válido no carregamento | B35: =IFERROR(COUNTIFS(FOLLOWUP!$AZ$2:$AZ$2000,"Sim",FOLLOWUP!$AP$2:$AP$2000,">="&$B$3,FOLLOWUP!$AP$2:$AP$2000,"<"&DATE(YEAR($B$3),MONTH($B$3)+1,1))/$B$31,0) -> 0.75
A36: % averbados antes da saída | B36: =IFERROR(COUNTIFS(AVERBACOES!$R$2:$R$2000,"Sim",AVERBACOES!$M$2:$M$2000,">="&$B$3)/COUNTIFS(AVERBACOES!$M$2:$M$2000,">="&$B$3),0) -> 1
A38: Monitoramento (mês)
A39: Ocorrências no mês | B39: =COUNTIFS(OCORRENCIAS!$E$2:$E$2000,">="&$B$3) -> 1
A40: Tempo médio até 1º contato (min) | B40: =IFERROR(AVERAGEIFS(OCORRENCIAS!$X$2:$X$2000,OCORRENCIAS!$E$2:$E$2000,">="&$B$3),0) -> 5
A41: % falsos positivos | B41: =IFERROR(COUNTIFS(OCORRENCIAS!$S$2:$S$2000,"Encerrada-Falso positivo",OCORRENCIAS!$E$2:$E$2000,">="&$B$3)/MAX(COUNTIFS(OCORRENCIAS!$E$2:$E$2000,">="&$B$3),1),0) -> 0
A42: Perdas de sinal no mês | B42: =COUNTIFS(OCORRENCIAS!$F$2:$F$2000,"Perda de sinal",OCORRENCIAS!$E$2:$E$2000,">="&$B$3) -> 0
A43: NC de PGR no mês | B43: =COUNTIFS(OCORRENCIAS!$U$2:$U$2000,"Sim",OCORRENCIAS!$E$2:$E$2000,">="&$B$3) -> 0
A45: Fronteira e sinistros
...

Sheet FOLLOWUP
A1: ID_VIAGEM | B1: Data abertura | C1: ★Placa | D1: Placa carreta 1 | E1: Placa carreta 2 | F1: ★Tipo de veículo | G1: Vínculo veículo | H1: ID motorista | I1: ★Nome do motorista | J1: Motorista operando | K1: ID motorista 2 | L1: Nome motorista 2 | M1: Status geral motorista | N1: ★Motorista validado GR | O1: Nº liberação GR | P1: Validade consulta GR | Q1: ★Motorista validado seguradora | R1: Nº liberação seguradora | S1: Validade consulta seguradora | T1: Valor máx. perfil motorista (R$) | U1: Motorista 2 validado (GR e seguradora) | V1: Veículo validado GR | W1: Cliente/embarcador | X1: Mercadoria | Y1: Categoria PGR | Z1: Valor da carga | AA1: Moeda | AB1: Valor da carga (R$) | AC1: Faixa PGR (oculta) | AD1: Faixa PGR | AE1: Exigências PGR | AF1: Isca exigida | AG1: Escolta exigida (qtd) | AH1: Acima do LMG | AI1: Origem | AJ1: Destino | AK1: País destino | AL1: Países trânsito | AM1: Posto de fronteira | AN1: Rota homologada | AO1: ★Data de carregamento | AP1: Data/hora carregamento real | AQ1: Início viagem (macro início) | AR1: ★Tipo de rastreador | AS1: ★Número do rastreador | AT1: Rastreador redundante/isca | AU1: Cobertura exterior rastreador | AV1: ★Está espelhado | AW1: Qtde destinos espelhados | AX1: Espelhado GR transportadora | AY1: Antecedência espelhamento (h) | AZ1: ★Checklist feito | BA1: Validade checklist | BB1: ★SMP feita | BC1: Nº SMP | BD1: Status SMP | BE1: GR responsável | BF1: ★Averbado | BG1: Nº averbação | BH1: CRT nº | BI1: MIC/DTA nº | BJ1: CT-e/MDF-e nacional | BK1: Docs internacionais OK | BL1: ★Status | BM1: Cód. status (oculta) | BN1: ★Veículo carregou | BO1: ★Veículo em viagem | BP1: ★Veículo em fronteira | BQ1: ★Veículo chegou | BR1: Data/hora chegada destino | BS1: Descarregou | BT1: ★Localização atual | BU1: Última posição cidade/UF/país | BV1: Última posição data/hora (oculta) | BW1: Horas sem sinal | BX1: Situação sinal | BY1: ETA fronteira | BZ1: ETA destino | CA1: Horas na fronteira (em curso) | CB1: Canal BR | CC1: Ocorrência aberta | CD1: APTO A SAIR | CE1: Liberação especial seguradora (acima LMG) | CF1: Pendências (oculta) | CG1: Pendências | CH1: Saída irregular | CI1: Viagem vigente da placa | CJ1: Resumo bot | CK1: Próximo passo | CL1: Responsável | CM1: Observação para o bot | CN1: Última atualização | CO1: Atualizado por | CP1: Desatualizado
A2: RGB-2026-0405 | B2: 46277.375 | C2: IYB5C34 | D2: IRS6F72 | F2: =IF(C2="","",IFERROR(INDEX(VEICULOS!$C:$C,MATCH(C2,VEICULOS!$A:$A,0)),"?")&IF(D2="",""," + "&IFERROR(INDEX(VEICULOS!$C:$C,MATCH(D2,VEICULOS!$A:$A,0)),"?"))&IF(E2="",""," + "&IFERROR(INDEX(VEICULOS!$C:$C,MATCH(E2,VEICULOS!$A:$A,0)),"?"))) -> Cavalo 6x4 + Carreta Sider 15,45m (107m3) | G2: =IF(C2="","",IFERROR(INDEX(VEICULOS!$I:$I,MATCH(C2,VEICULOS!$A:$A,0)),"Não cadastrado")) -> Frota própria (CLT) | H2: MOT-005 | I2: =IF(H2="","",IFERROR(INDEX(MOTORISTAS!$B:$B,MATCH(H2,MOTORISTAS!$A:$A,0)),"Não cadastrado")) -> Sérgio Pinto Machado | J2: Sim | L2: =IF(K2="","",IFERROR(INDEX(MOTORISTAS!$B:$B,MATCH(K2,MOTORISTAS!$A:$A,0)),"Não cadastrado")) | M2: =IF(H2="","",IFERROR(INDEX(MOTORISTAS!$AA:$AA,MATCH(H2,MOTORISTAS!$A:$A,0)),"Não cadastrado")) -> Apto | N2: =IF(H2="","",IF(COUNTIFS(CONSULTAS!$C$2:$C$2000,H2,CONSULTAS!$E$2:$E$2000,"GR",CONSULTAS!$S$2:$S$2000,"Sim")>0,"Sim","Não")) -> Sim | O2: =IF(H2="","",IFERROR(INDEX(CONSULTAS!$L:$L,MATCH(H2&"#GR",CONSULTAS!$T:$T,0)),"—")) -> LIB-551004 | P2: =IF(H2="","",IFERROR(INDEX(CONSULTAS!$Q:$Q,MATCH(H2&"#GR",CONSULTAS!$T:$T,0)),"")) -> 46402 | Q2: =IF(H2="","",IF(COUNTIFS(CONSULTAS!$C$2:$C$2000,H2,CONSULTAS!$E$2:$E$2000,"Seguradora",CONSULTAS!$S$2:$S$2000,"Sim")>0,"Sim","Não")) -> Sim | R2: =IF(H2="","",IFERROR(INDEX(CONSULTAS!$L:$L,MATCH(H2&"#Seguradora",CONSULTAS!$T:$T,0)),"—")) -> SEG-98870 | S2: =IF(H2="","",IFERROR(INDEX(CONSULTAS!$Q:$Q,MATCH(H2&"#Seguradora",CONSULTAS!$T:$T,0)),"")) -> 46402 | T2: =IF(H2="","",IFERROR(INDEX(CONSULTAS!$N:$N,MATCH(H2&"#GR",CONSULTAS!$T:$T,0)),"")) -> 1500000 | U2: =IF(K2="","N/A",IF(AND(COUNTIFS(CONSULTAS!$C$2:$C$2000,K2,CONSULTAS!$E$2:$E$2000,"GR",CONSULTAS!$S$2:$S$2000,"Sim")>0,COUNTIFS(CONSULTAS!$C$2:$C$2000,K2,CONSULTAS!$E$2:$E$2000,"Seguradora",CONSULTAS!$S$2:$S$2000,"Sim")>0),"Sim","Não")) -> N/A | V2: =IF(C2="","",IFERROR(INDEX(VEICULOS!$X:$X,MATCH(C2,VEICULOS!$A:$A,0)),"Não")) -> Sim | W2: Cliente Exemplo CL | X2: Máquinas agrícolas - peças | Y2: Carga seca geral | Z2: 610000 | AA2: BRL | AB2: =IF(Z2="","",IF(AA2="USD",Z2*P_TAXA_USD,Z2)) -> 610000 | AC2: =IF(OR(Y2="",AB2=""),0,SUMPRODUCT((PGR_REGRAS!$C$2:$C$61=Y2)*(PGR_REGRAS!$D$2:$D$61<=AB2)*(PGR_REGRAS!$E$2:$E$61>=AB2)*(PGR_REGRAS!$C$2:$C$61<>"")*ROW(PGR_REGRAS!$C$2:$C$61))) -> 3 | AD2: =IF(AC2=0,IF(Y2="","","Sem regra - consultar seguradora"),INDEX(PGR_REGRAS!$A:$A,AC2)) -> PGR-02 | AE2: =IF(AC2=0,"",INDEX(PGR_REGRAS!$T:$T,AC2)) -> Cadastro + rastreador 24h + espelhamento 2h antes; proibido terceiro (exemplo) | AF2: =IF(AC2=0,"",INDEX(PGR_REGRAS!$I:$I,AC2)) -> Não | AG2: =IF(AC2=0,"",INDEX(PGR_REGRAS!$K:$K,AC2)) -> 0 | AH2: =IF(AB2="","",IF(AB2>P_LMG_REF,"Sim","Não")) -> Não | AI2: Uruguaiana/RS/BR | AJ2: Santiago | AK2: CL | AL2: AR | AM2: Uruguaiana-Paso de los Libres | AN2: Sim | AO2: 46279 | AP2: 46279.25 | AQ2: 46279.333 | AR2: =IF(C2="","",IFERROR(INDEX(RASTREADORES!$F:$F,MATCH(C2&"#Principal",RASTREADORES!$Y:$Y,0))&" ("&INDEX(RASTREADORES!$G:$G,MATCH(C2&"#Principal",RASTREADORES!$Y:$Y,0))&")","Sem rastreador principal")) -> Autotrac PRIME (Híbrido (satélite+4G)) | AS2: =IF(C2="","",IFERROR(INDEX(RASTREADORES!$H:$H,MATCH(C2&"#Principal",RASTREADORES!$Y:$Y,0)),"—")) -> 7714410 | AT2: =IF(C2="","",IFERROR(INDEX(RASTREADORES!$A:$A,MATCH(C2&"#Redundante",RASTREADORES!$Y:$Y,0)),IFERROR(INDEX(RASTREADORES!$A:$A,MATCH(C2&"#Isca retornável",RASTREADORES!$Y:$Y,0)),IFERROR(INDEX(RASTREADORES!$A:$A,MATCH(C2&"#Isca descartável",RASTREADORES!$Y:$Y,0)),"Nenhum")))) -> Nenhum | AU2: =IF(C2="","",IFERROR(INDEX(RASTREADORES!$L:$L,MATCH(C2&"#Principal",RASTREADORES!$Y:$Y,0)),"")) -> A confirmar | AV2: =IF(C2="","",IF(COUNTIFS(ESPELHAMENTOS!$B$2:$B$2000,C2,ESPELHAMENTOS!$O$2:$O$2000,"Sim")>0,"Sim","Não")) -> Não | AW2: =IF(C2="","",COUNTIFS(ESPELHAMENTOS!$B$2:$B$2000,C2,ESPELHAMENTOS!$O$2:$O$2000,"Sim")) -> 0 | AX2: =IF(C2="","",IF(COUNTIFS(ESPELHAMENTOS!$B$2:$B$2000,C2,ESPELHAMENTOS!$O$2:$O$2000,"Sim",ESPELHAMENTOS!$E$2:$E$2000,"GR transportadora")>0,"Sim","Não")) -> Não | AY2: =IF(OR(AQ2="",C2=""),"",IFERROR(ROUND((AQ2-SUMPRODUCT(MIN((ESPELHAMENTOS!$C$2:$C$2000=A2)*ESPELHAMENTOS!$H$2:$H$2000+(ESPELHAMENTOS!$C$2:$C$2000<>A2)*99999)))*24,1),"")) -> 3 | AZ2: =IF(C2="","",IF(COUNTIFS(CHECKLISTS!$B$2:$B$2000,C2,CHECKLISTS!$AH$2:$AH$2000,"Válido",CHECKLISTS!$AG$2:$AG$2000,">="&INT(IF(AO2="",TODAY(),AO2)))+COUNTIFS(CHECKLISTS!$B$2:$B$2000,C2,CHECKLISTS!$AH$2:$AH$2000,"Vence <=7d",CHECKLISTS!$AG$2:$AG$2000,">="&INT(IF(AO2="",TODAY(),AO2)))>0,"Sim","Não")) -> Sim | BA2: =IF(C2="","",IF(COUNTIFS(CHECKLISTS!$B$2:$B$2000,C2,CHECKLISTS!$AF$2:$AF$2000,"Aprovado")=0,"",SUMPRODUCT(MAX((CHECKLISTS!$B$2:$B$2000=C2)*CHECKLISTS!$AG$2:$AG$2000)))) | BB2: =IF(A2="","",IF(COUNTIFS(SMP!$B$2:$B$2000,A2,SMP!$I$2:$I$2000,"Liberada")+COUNTIFS(SMP!$B$2:$B$2000,A2,SMP!$I$2:$I$2000,"Em andamento")+COUNTIFS(SMP!$B$2:$B$2000,A2,SMP!$I$2:$I$2000,"Finalizada")>0,"Sim","Não")) -> Sim | BC2: =IF(A2="","",IFERROR(INDEX(SMP!$A:$A,MATCH(A2,SMP!$B:$B,0)),"—")) -> SMP-88210 | BD2: =IF(A2="","",IFERROR(INDEX(SMP!$I:$I,MATCH(A2,SMP!$B:$B,0)),"Não aberta")) -> Finalizada | BE2: =IF(A2="","",IFERROR(INDEX(SMP!$D:$D,MATCH(A2,SMP!$B:$B,0)),"")) -> A DEFINIR | BF2: =IF(A2="","",IF(COUNTIFS(AVERBACOES!$B$2:$B$2000,A2,AVERBACOES!$Q$2:$Q$2000,"Averbado completo")+COUNTIFS(AVERBACOES!$B$2:$B$2000,A2,AVERBACOES!$Q$2:$Q$2000,"Averbado CRT")+COUNTIFS(AVERBACOES!$B$2:$B$2000,A2,AVERBACOES!$Q$2:$Q$2000,"Averbado CT-e")+COUNTIFS(AVERBACOES!$B$2:$B$2000,A2,AVERBACOES!$Q$2:$Q$2000,"Averbado MDF-e")+COUNTIFS(AVERBACOES!$B$2:$B$2000,A2,AVERBACOES!$Q$2:$Q$2000,"Averbado pelo embarcador")>0,"Sim","Não")) -> Sim | BG2: =IF(A2="","",IFERROR(INDEX(AVERBACOES!$L:$L,MATCH(A2,AVERBACOES!$B:$B,0)),"—")) -> AV-2026-004401 | BH2: BR.1234.00440 | BI2: 2026BR000701 | BK2: Sim | BL2: 20 Finalizado | BM2: =IF(BL2="",0,VALUE(LEFT(BL2,2))) -> 20 | BN2: =IF(A2="","",IF(AP2<>"","Sim","Não")) -> Sim | BO2: =IF(A2="","",IF(OR(BM2=8,BM2=9,BM2=10,BM2=11,BM2=15),"Sim","Não")) -> Não | BP2: =IF(A2="","",IF(AND(BM2>=12,BM2<=14),"Sim","Não")) -> Não | BQ2: =IF(A2="","",IF(OR(AND(BM2>=16,BM2<=20),BR2<>""),"Sim","Não")) -> Sim | BR2: 46283.625 | BS2: =IF(A2="","",IF(OR(BM2=18,BM2=19,BM2=20),"Sim","Não")) -> Sim | BT2: =IF(C2="","",IF(BV2=0,"Sem posição registrada",IFERROR(INDEX(POSICOES!$E:$E,MATCH(C2&"#"&ROUND(BV2*1440,0),POSICOES!$R:$R,0)),"?"))) -> Depósito destino - Rosario | BU2: =IF(OR(C2="",BV2=0),"",IFERROR(INDEX(POSICOES!$F:$F,MATCH(C2&"#"&ROUND(BV2*1440,0),POSICOES!$R:$R,0))&"/"&INDEX(POSICOES!$G:$G,MATCH(C2&"#"&ROUND(BV2*1440,0),POSICOES!$R:$R,0))&" - "&INDEX(POSICOES!$H:$H,MATCH(C2&"#"&ROUND(BV2*1440,0),POSICOES!$R:$R,0)),"")) -> Rosario/Santa Fe - AR | BV2: =IF(C2="",0,SUMPRODUCT(MAX((POSICOES!$C$2:$C$3000=C2)*POSICOES!$B$2:$B$3000))) -> 46290.333 | BW2: =IF(OR(BV2=0,BM2=0,BM2>=20),"",ROUND((NOW()-BV2)*24,1)) | BX2: =IF(BW2="","",IF(BW2<P_SINAL_ALERTA,"Online",IF(BW2<P_SINAL_CRIT,"Sem sinal 1-4h","Sem sinal >4h"))) | CA2: =IF(A2="","",IF(COUNTIFS(FRONTEIRA!$B$2:$B$2000,A2,FRONTEIRA!$AA$2:$AA$2000,"Sim")=0,"",ROUND(SUMIFS(FRONTEIRA!$Y$2:$Y$2000,FRONTEIRA!$B$2:$B$2000,A2,FRONTEIRA!$AA$2:$AA$2000,"Sim"),1))) | CB2: =IF(A2="","",IFERROR(INDEX(FRONTEIRA!$L:$L,MATCH(A2,FRONTEIRA!$B:$B,0)),"")) | CC2: =IF(A2="","",IF(COUNTIFS(OCORRENCIAS!$B$2:$B$2000,A2,OCORRENCIAS!$Z$2:$Z$2000,"Sim")>0,"Sim","Não")) -> Não | CD2: =IF(A2="","",IF(AND(N2="Sim",Q2="Sim",OR(U2="Sim",U2="N/A"),V2="Sim",M2<>"Inapto",AZ2="Sim",AV2="Sim",BB2="Sim",BF2="Sim",OR(BK2="Sim",BK2="N/A"),OR(T2="",AB2="",AB2<=T2),OR(AH2<>"Sim",CE2="Sim")),"APTO","BLOQUEADO")) -> BLOQUEADO | CF2: =IF(N2<>"Sim","Motorista GR; ","")&IF(Q2<>"Sim","Motorista seguradora; ","")&IF(U2="Não","Motorista 2; ","")&IF(V2<>"Sim","Veículo GR; ","")&IF(M2="Inapto","Documentos do motorista; ","")&IF(AZ2<>"Sim","Checklist; ","")&IF(AV2<>"Sim","Espelhamento; ","")&IF(BB2<>"Sim","SMP; ","")&IF(BF2<>"Sim","Averbação; ","")&IF(BK2="Não","Docs internacionais; ","")&IF(AND(T2<>"",AB2<>"",AB2>T2),"Valor acima do perfil; ","")&IF(AND(AH2="Sim",CE2<>"Sim"),"Acima do LMG sem aprovação; ","") -> Espelhamento; | CG2: =IF(A2="","",IF(CF2="","Nenhuma",LEFT(CF2,LEN(CF2)-2))) -> Espelhamento | CH2: =IF(A2="","",IF(AND(OR(BO2="Sim",BP2="Sim"),CD2="BLOQUEADO"),"Sim","Não")) -> Não | CI2: =IF(OR(C2="",BM2=0,BM2>=20),"Não",IF(B2=SUMPRODUCT(MAX((C$2:C$2000=C2)*(BM$2:BM$2000>0)*(BM$2:BM$2000<20)*B$2:B$2000)),"Sim","Não")) -> Não | CJ2: =IF(A2="","","Viagem "&A2&" - Placa "&C2&" - "&BL2&" - Local: "&BT2&" - Motorista: "&I2&" (GR: "&N2&"; Seguradora: "&Q2&") - Rastreador: "&AR2&" no "&AS2&" - Espelhado: "&AV2&" - Checklist: "&AZ2&" - SMP: "&BB2&" - Averbado: "&BF2&" - Apto: "&CD2&" - Pendencias: "&CG2) -> Viagem RGB-2026-0405 - Placa IYB5C34 - 20 Finalizado - Local: Depósito destino - Rosario - Motorista: Sérgio Pinto Machado (GR: Sim; Seguradora: Sim) - Rastreador: Autotrac PRIME (Híbrido (satélite+4G)) no 7714410 - Espelhado: Não - Checklist: Sim - SMP: Sim - Averbado: Sim - Apto: BLOQUEADO - Pendencias: Espelhamento | CM2: Viagem finalizada sem intercorrências. | CN2: 46287.757 | CO2: Analista GR 1 | CP2: =IF(OR(CN2="",BM2<7,BM2>=20),"",IF((NOW()-CN2)*24>P_ATUALIZ_MAX_H,"Sim","Não"))
A3: RGB-2026-0412 | B3: 46283.417 | C3: IYA3B21 | D3: IRS1B10 | F3: =IF(C3="","",IFERROR(INDEX(VEICULOS!$C:$C,MATCH(C3,VEICULOS!$A:$A,0)),"?")&IF(D3="",""," + "&IFERROR(INDEX(VEICULOS!$C:$C,MATCH(D3,VEICULOS!$A:$A,0)),"?"))&IF(E3="",""," + "&IFERROR(INDEX(VEICULOS!$C:$C,MATCH(E3,VEICULOS!$A:$A,0)),"?"))) -> Cavalo 6x2 + Carreta Sider 15,45m (107m3) | G3: =IF(C3="","",IFERROR(INDEX(VEICULOS!$I:$I,MATCH(C3,VEICULOS!$A:$A,0)),"Não cadastrado")) -> Frota própria (CLT) | H3: MOT-001 | I3: =IF(H3="","",IFERROR(INDEX(MOTORISTAS!$B:$B,MATCH(H3,MOTORISTAS!$A:$A,0)),"Não cadastrado")) -> João Carlos Pereira | J3: Sim | L3: =IF(K3="","",IFERROR(INDEX(MOTORISTAS!$B:$B,MATCH(K3,MOTORISTAS!$A:$A,0)),"Não cadastrado")) | M3: =IF(H3="","",IFERROR(INDEX(MOTORISTAS!$AA:$AA,MATCH(H3,MOTORISTAS!$A:$A,0)),"Não cadastrado")) -> Apto | N3: =IF(H3="","",IF(COUNTIFS(CONSULTAS!$C$2:$C$2000,H3,CONSULTAS!$E$2:$E$2000,"GR",CONSULTAS!$S$2:$S$2000,"Sim")>0,"Sim","Não")) -> Sim | O3: =IF(H3="","",IFERROR(INDEX(CONSULTAS!$L:$L,MATCH(H3&"#GR",CONSULTAS!$T:$T,0)),"—")) -> LIB-558812 | P3: =IF(H3="","",IFERROR(INDEX(CONSULTAS!$Q:$Q,MATCH(H3&"#GR",CONSULTAS!$T:$T,0)),"")) -> 46420 | Q3: =IF(H3="","",IF(COUNTIFS(CONSULTAS!$C$2:$C$2000,H3,CONSULTAS!$E$2:$E$2000,"Seguradora",CONSULTAS!$S$2:$S$2000,"Sim")>0,"Sim","Não")) -> Sim | R3: =IF(H3="","",IFERROR(INDEX(CONSULTAS!$L:$L,MATCH(H3&"#Seguradora",CONSULTAS!$T:$T,0)),"—")) -> SEG-99102 | S3: =IF(H3="","",IFERROR(INDEX(CONSULTAS!$Q:$Q,MATCH(H3&"#Seguradora",CONSULTAS!$T:$T,0)),"")) -> 46420 | T3: =IF(H3="","",IFERROR(INDEX(CONSULTAS!$N:$N,MATCH(H3&"#GR",CONSULTAS!$T:$T,0)),"")) -> 1500000 | U3: =IF(K3="","N/A",IF(AND(COUNTIFS(CONSULTAS!$C$2:$C$2000,K3,CONSULTAS!$E$2:$E$2000,"GR",CONSULTAS!$S$2:$S$2000,"Sim")>0,COUNTIFS(CONSULTAS!$C$2:$C$2000,K3,CONSULTAS!$E$2:$E$2000,"Seguradora",CONSULTAS!$S$2:$S$2000,"Sim")>0),"Sim","Não")) -> N/A | V3: =IF(C3="","",IFERROR(INDEX(VEICULOS!$X:$X,MATCH(C3,VEICULOS!$A:$A,0)),"Não")) -> Sim | W3: Embarcador siderúrgico (exemplo) | X3: Bobinas de aço | Y3: Aço/siderúrgicos | Z3: 820000 | AA3: BRL | AB3: =IF(Z3="","",IF(AA3="USD",Z3*P_TAXA_USD,Z3)) -> 820000 | AC3: =IF(OR(Y3="",AB3=""),0,SUMPRODUCT((PGR_REGRAS!$C$2:$C$61=Y3)*(PGR_REGRAS!$D$2:$D$61<=AB3)*(PGR_REGRAS!$E$2:$E$61>=AB3)*(PGR_REGRAS!$C$2:$C$61<>"")*ROW(PGR_REGRAS!$C$2:$C$61))) -> 5 | AD3: =IF(AC3=0,IF(Y3="","","Sem regra - consultar seguradora"),INDEX(PGR_REGRAS!$A:$A,AC3)) -> PGR-04 | AE3: =IF(AC3=0,"",INDEX(PGR_REGRAS!$T:$T,AC3)) -> Cadastro + rastreador (exemplo) | AF3: =IF(AC3=0,"",INDEX(PGR_REGRAS!$I:$I,AC3)) -> Não | AG3: =IF(AC3=0,"",INDEX(PGR_REGRAS!$K:$K,AC3)) -> 0 | AH3: =IF(AB3="","",IF(AB3>P_LMG_REF,"Sim","Não")) -> Não | AI3: Barra Mansa/RJ/BR | AJ3: Rosario | AK3: AR | AM3: Uruguaiana-Paso de los Libres | AN3: Sim | AO3: 46286 | AP3: 46286.667 | AQ3: 46287.299 | AR3: =IF(C3="","",IFERROR(INDEX(RASTREADORES!$F:$F,MATCH(C3&"#Principal",RASTREADORES!$Y:$Y,0))&" ("&INDEX(RASTREADORES!$G:$G,MATCH(C3&"#Principal",RASTREADORES!$Y:$Y,0))&")","Sem rastreador principal")) -> Autotrac PRIME (Híbrido (satélite+4G)) | AS3: =IF(C3="","",IFERROR(INDEX(RASTREADORES!$H:$H,MATCH(C3&"#Principal",RASTREADORES!$Y:$Y,0)),"—")) -> 7712345 | AT3: =IF(C3="","",IFERROR(INDEX(RASTREADORES!$A:$A,MATCH(C3&"#Redundante",RASTREADORES!$Y:$Y,0)),IFERROR(INDEX(RASTREADORES!$A:$A,MATCH(C3&"#Isca retornável",RASTREADORES!$Y:$Y,0)),IFERROR(INDEX(RASTREADORES!$A:$A,MATCH(C3&"#Isca descartável",RASTREADORES!$Y:$Y,0)),"Nenhum")))) -> EQ-050 | AU3: =IF(C3="","",IFERROR(INDEX(RASTREADORES!$L:$L,MATCH(C3&"#Principal",RASTREADORES!$Y:$Y,0)),"")) -> A confirmar | AV3: =IF(C3="","",IF(COUNTIFS(ESPELHAMENTOS!$B$2:$B$2000,C3,ESPELHAMENTOS!$O$2:$O$2000,"Sim")>0,"Sim","Não")) -> Sim | AW3: =IF(C3="","",COUNTIFS(ESPELHAMENTOS!$B$2:$B$2000,C3,ESPELHAMENTOS!$O$2:$O$2000,"Sim")) -> 2 | AX3: =IF(C3="","",IF(COUNTIFS(ESPELHAMENTOS!$B$2:$B$2000,C3,ESPELHAMENTOS!$O$2:$O$2000,"Sim",ESPELHAMENTOS!$E$2:$E$2000,"GR transportadora")>0,"Sim","Não")) -> Sim | AY3: =IF(OR(AQ3="",C3=""),"",IFERROR(ROUND((AQ3-SUMPRODUCT(MIN((ESPELHAMENTOS!$C$2:$C$2000=A3)*ESPELHAMENTOS!$H$2:$H$2000+(ESPELHAMENTOS!$C$2:$C$2000<>A3)*99999)))*24,1),"")) -> 2.7 | AZ3: =IF(C3="","",IF(COUNTIFS(CHECKLISTS!$B$2:$B$2000,C3,CHECKLISTS!$AH$2:$AH$2000,"Válido",CHECKLISTS!$AG$2:$AG$2000,">="&INT(IF(AO3="",TODAY(),AO3)))+COUNTIFS(CHECKLISTS!$B$2:$B$2000,C3,CHECKLISTS!$AH$2:$AH$2000,"Vence <=7d",CHECKLISTS!$AG$2:$AG$2000,">="&INT(IF(AO3="",TODAY(),AO3)))>0,"Sim","Não")) -> Sim | BA3: =IF(C3="","",IF(COUNTIFS(CHECKLISTS!$B$2:$B$2000,C3,CHECKLISTS!$AF$2:$AF$2000,"Aprovado")=0,"",SUMPRODUCT(MAX((CHECKLISTS!$B$2:$B$2000=C3)*CHECKLISTS!$AG$2:$AG$2000)))) | BB3: =IF(A3="","",IF(COUNTIFS(SMP!$B$2:$B$2000,A3,SMP!$I$2:$I$2000,"Liberada")+COUNTIFS(SMP!$B$2:$B$2000,A3,SMP!$I$2:$I$2000,"Em andamento")+COUNTIFS(SMP!$B$2:$B$2000,A3,SMP!$I$2:$I$2000,"Finalizada")>0,"Sim","Não")) -> Sim | BC3: =IF(A3="","",IFERROR(INDEX(SMP!$A:$A,MATCH(A3,SMP!$B:$B,0)),"—")) -> SMP-88231 | BD3: =IF(A3="","",IFERROR(INDEX(SMP!$I:$I,MATCH(A3,SMP!$B:$B,0)),"Não aberta")) -> Em andamento | BE3: =IF(A3="","",IFERROR(INDEX(SMP!$D:$D,MATCH(A3,SMP!$B:$B,0)),"")) -> A DEFINIR | BF3: =IF(A3="","",IF(COUNTIFS(AVERBACOES!$B$2:$B$2000,A3,AVERBACOES!$Q$2:$Q$2000,"Averbado completo")+COUNTIFS(AVERBACOES!$B$2:$B$2000,A3,AVERBACOES!$Q$2:$Q$2000,"Averbado CRT")+COUNTIFS(AVERBACOES!$B$2:$B$2000,A3,AVERBACOES!$Q$2:$Q$2000,"Averbado CT-e")+COUNTIFS(AVERBACOES!$B$2:$B$2000,A3,AVERBACOES!$Q$2:$Q$2000,"Averbado MDF-e")+COUNTIFS(AVERBACOES!$B$2:$B$2000,A3,AVERBACOES!$Q$2:$Q$2000,"Averbado pelo embarcador")>0,"Sim","Não")) -> Sim | BG3: =IF(A3="","",IFERROR(INDEX(AVERBACOES!$L:$L,MATCH(A3,AVERBACOES!$B:$B,0)),"—")) -> AV-2026-004512 | BH3: BR.1234.00456 | BI3: 2026BR000789 | BK3: Sim | BL3: 13 Fronteira - despacho/parametrização | BM3: =IF(BL3="",0,VALUE(LEFT(BL3,2))) -> 13 | BN3: =IF(A3="","",IF(AP3<>"","Sim","Não")) -> Sim | BO3: =IF(A3="","",IF(OR(BM3=8,BM3=9,BM3=10,BM3=11,BM3=15),"Sim","Não")) -> Não | BP3: =IF(A3="","",IF(AND(BM3>=12,BM3<=14),"Sim","Não")) -> Sim | BQ3: =IF(A3="","",IF(OR(AND(BM3>=16,BM3<=20),BR3<>""),"Sim","Não")) -> Não | BS3: =IF(A3="","",IF(OR(BM3=18,BM3=19,BM3=20),"Sim","Não")) -> Não | BT3: =IF(C3="","",IF(BV3=0,"Sem posição registrada",IFERROR(INDEX(POSICOES!$E:$E,MATCH(C3&"#"&ROUND(BV3*1440,0),POSICOES!$R:$R,0)),"?"))) -> Porto Seco Rodoviário de Uruguaiana - pátio | BU3: =IF(OR(C3="",BV3=0),"",IFERROR(INDEX(POSICOES!$F:$F,MATCH(C3&"#"&ROUND(BV3*1440,0),POSICOES!$R:$R,0))&"/"&INDEX(POSICOES!$G:$G,MATCH(C3&"#"&ROUND(BV3*1440,0),POSICOES!$R:$R,0))&" - "&INDEX(POSICOES!$H:$H,MATCH(C3&"#"&ROUND(BV3*1440,0),POSICOES!$R:$R,0)),"")) -> Uruguaiana/RS - BR | BV3: =IF(C3="",0,SUMPRODUCT(MAX((POSICOES!$C$2:$C$3000=C3)*POSICOES!$B$2:$B$3000))) -> 46290.562 | BW3: =IF(OR(BV3=0,BM3=0,BM3>=20),"",ROUND((NOW()-BV3)*24,1)) -> 6.1 | BX3: =IF(BW3="","",IF(BW3<P_SINAL_ALERTA,"Online",IF(BW3<P_SINAL_CRIT,"Sem sinal 1-4h","Sem sinal >4h"))) -> Sem sinal >4h | BZ3: 46291.833 | CA3: =IF(A3="","",IF(COUNTIFS(FRONTEIRA!$B$2:$B$2000,A3,FRONTEIRA!$AA$2:$AA$2000,"Sim")=0,"",ROUND(SUMIFS(FRONTEIRA!$Y$2:$Y$2000,FRONTEIRA!$B$2:$B$2000,A3,FRONTEIRA!$AA$2:$AA$2000,"Sim"),1))) -> 83.6 | CB3: =IF(A3="","",IFERROR(INDEX(FRONTEIRA!$L:$L,MATCH(A3,FRONTEIRA!$B:$B,0)),"")) -> Verde | CC3: =IF(A3="","",IF(COUNTIFS(OCORRENCIAS!$B$2:$B$2000,A3,OCORRENCIAS!$Z$2:$Z$2000,"Sim")>0,"Sim","Não")) -> Não | CD3: =IF(A3="","",IF(AND(N3="Sim",Q3="Sim",OR(U3="Sim",U3="N/A"),V3="Sim",M3<>"Inapto",AZ3="Sim",AV3="Sim",BB3="Sim",BF3="Sim",OR(BK3="Sim",BK3="N/A"),OR(T3="",AB3="",AB3<=T3),OR(AH3<>"Sim",CE3="Sim")),"APTO","BLOQUEADO")) -> APTO | CF3: =IF(N3<>"Sim","Motorista GR; ","")&IF(Q3<>"Sim","Motorista seguradora; ","")&IF(U3="Não","Motorista 2; ","")&IF(V3<>"Sim","Veículo GR; ","")&IF(M3="Inapto","Documentos do motorista; ","")&IF(AZ3<>"Sim","Checklist; ","")&IF(AV3<>"Sim","Espelhamento; ","")&IF(BB3<>"Sim","SMP; ","")&IF(BF3<>"Sim","Averbação; ","")&IF(BK3="Não","Docs internacionais; ","")&IF(AND(T3<>"",AB3<>"",AB3>T3),"Valor acima do perfil; ","")&IF(AND(AH3="Sim",CE3<>"Sim"),"Acima do LMG sem aprovação; ","") | CG3: =IF(A3="","",IF(CF3="","Nenhuma",LEFT(CF3,LEN(CF3)-2))) -> Nenhuma | CH3: =IF(A3="","",IF(AND(OR(BO3="Sim",BP3="Sim"),CD3="BLOQUEADO"),"Sim","Não")) -> Não | CI3: =IF(OR(C3="",BM3=0,BM3>=20),"Não",IF(B3=SUMPRODUCT(MAX((C$2:C$2000=C3)*(BM$2:BM$2000>0)*(BM$2:BM$2000<20)*B$2:B$2000)),"Sim","Não")) -> Sim | CJ3: =IF(A3="","","Viagem "&A3&" - Placa "&C3&" - "&BL3&" - Local: "&BT3&" - Motorista: "&I3&" (GR: "&N3&"; Seguradora: "&Q3&") - Rastreador: "&AR3&" no "&AS3&" - Espelhado: "&AV3&" - Checklist: "&AZ3&" - SMP: "&BB3&" - Averbado: "&BF3&" - Apto: "&CD3&" - Pendencias: "&CG3) -> Viagem RGB-2026-0412 - Placa IYA3B21 - 13 Fronteira - despacho/parametrização - Local: Porto Seco Rodoviário de Uruguaiana - pátio - Motorista: João Carlos Pereira (GR: Sim; Seguradora: Sim) - Rastreador: Autotrac PRIME (Híbrido (satélite+4G)) no 7712345 - Espelhado: Sim - Checklist: Sim - SMP: Sim - Averbado: Sim - Apto: APTO - Pendencias: Nenhuma | CM3: Canal verde BR; aguardando parametrização AR. | CN3: 46290.58 | CO3: Analista GR 1 | CP3: =IF(OR(CN3="",BM3<7,BM3>=20),"",IF((NOW()-CN3)*24>P_ATUALIZ_MAX_H,"Sim","Não")) -> Sim
A4: RGB-2026-0415 | B4: 46287.333 | C4: IYD2E67 | D4: IRS3D44 | F4: =IF(C4="","",IFERROR(INDEX(VEICULOS!$C:$C,MATCH(C4,VEICULOS!$A:$A,0)),"?")&IF(D4="",""," + "&IFERROR(INDEX(VEICULOS!$C:$C,MATCH(D4,VEICULOS!$A:$A,0)),"?"))&IF(E4="",""," + "&IFERROR(INDEX(VEICULOS!$C:$C,MATCH(E4,VEICULOS!$A:$A,0)),"?"))) -> Cavalo 6x2 + Carreta Aberta 15m (100m3) | G4: =IF(C4="","",IFERROR(INDEX(VEICULOS!$I:$I,MATCH(C4,VEICULOS!$A:$A,0)),"Não cadastrado")) -> Frota própria (CLT) | H4: MOT-002 | I4: =IF(H4="","",IFERROR(INDEX(MOTORISTAS!$B:$B,MATCH(H4,MOTORISTAS!$A:$A,0)),"Não cadastrado")) -> Luis Alberto Fagundes | J4: Sim | L4: =IF(K4="","",IFERROR(INDEX(MOTORISTAS!$B:$B,MATCH(K4,MOTORISTAS!$A:$A,0)),"Não cadastrado")) | M4: =IF(H4="","",IFERROR(INDEX(MOTORISTAS!$AA:$AA,MATCH(H4,MOTORISTAS!$A:$A,0)),"Não cadastrado")) -> Apto | N4: =IF(H4="","",IF(COUNTIFS(CONSULTAS!$C$2:$C$2000,H4,CONSULTAS!$E$2:$E$2000,"GR",CONSULTAS!$S$2:$S$2000,"Sim")>0,"Sim","Não")) -> Sim | O4: =IF(H4="","",IFERROR(INDEX(CONSULTAS!$L:$L,MATCH(H4&"#GR",CONSULTAS!$T:$T,0)),"—")) -> LIB-570331 | P4: =IF(H4="","",IFERROR(INDEX(CONSULTAS!$Q:$Q,MATCH(H4&"#GR",CONSULTAS!$T:$T,0)),"")) -> 46456 | Q4: =IF(H4="","",IF(COUNTIFS(CONSULTAS!$C$2:$C$2000,H4,CONSULTAS!$E$2:$E$2000,"Seguradora",CONSULTAS!$S$2:$S$2000,"Sim")>0,"Sim","Não")) -> Sim | R4: =IF(H4="","",IFERROR(INDEX(CONSULTAS!$L:$L,MATCH(H4&"#Seguradora",CONSULTAS!$T:$T,0)),"—")) -> SEG-99240 | S4: =IF(H4="","",IFERROR(INDEX(CONSULTAS!$Q:$Q,MATCH(H4&"#Seguradora",CONSULTAS!$T:$T,0)),"")) -> 46456 | T4: =IF(H4="","",IFERROR(INDEX(CONSULTAS!$N:$N,MATCH(H4&"#GR",CONSULTAS!$T:$T,0)),"")) -> 1000000 | U4: =IF(K4="","N/A",IF(AND(COUNTIFS(CONSULTAS!$C$2:$C$2000,K4,CONSULTAS!$E$2:$E$2000,"GR",CONSULTAS!$S$2:$S$2000,"Sim")>0,COUNTIFS(CONSULTAS!$C$2:$C$2000,K4,CONSULTAS!$E$2:$E$2000,"Seguradora",CONSULTAS!$S$2:$S$2000,"Sim")>0),"Sim","Não")) -> N/A | V4: =IF(C4="","",IFERROR(INDEX(VEICULOS!$X:$X,MATCH(C4,VEICULOS!$A:$A,0)),"Não")) -> Sim | W4: Cliente Exemplo CL | X4: Bobinas de papel | Y4: Carga seca geral | Z4: 95000 | AA4: USD | AB4: =IF(Z4="","",IF(AA4="USD",Z4*P_TAXA_USD,Z4)) -> 513000 | AC4: =IF(OR(Y4="",AB4=""),0,SUMPRODUCT((PGR_REGRAS!$C$2:$C$61=Y4)*(PGR_REGRAS!$D$2:$D$61<=AB4)*(PGR_REGRAS!$E$2:$E$61>=AB4)*(PGR_REGRAS!$C$2:$C$61<>"")*ROW(PGR_REGRAS!$C$2:$C$61))) -> 3 | AD4: =IF(AC4=0,IF(Y4="","","Sem regra - consultar seguradora"),INDEX(PGR_REGRAS!$A:$A,AC4)) -> PGR-02 | AE4: =IF(AC4=0,"",INDEX(PGR_REGRAS!$T:$T,AC4)) -> Cadastro + rastreador 24h + espelhamento 2h antes; proibido terceiro (exemplo) | AF4: =IF(AC4=0,"",INDEX(PGR_REGRAS!$I:$I,AC4)) -> Não | AG4: =IF(AC4=0,"",INDEX(PGR_REGRAS!$K:$K,AC4)) -> 0 | AH4: =IF(AB4="","",IF(AB4>P_LMG_REF,"Sim","Não")) -> Não | AI4: Uruguaiana/RS/BR (Armazém Geral Rigabras) | AJ4: Santiago | AK4: CL | AL4: AR | AM4: Uruguaiana-Paso de los Libres | AN4: Sim | AO4: 46289 | AP4: 46289.333 | AQ4: 46289.458 | AR4: =IF(C4="","",IFERROR(INDEX(RASTREADORES!$F:$F,MATCH(C4&"#Principal",RASTREADORES!$Y:$Y,0))&" ("&INDEX(RASTREADORES!$G:$G,MATCH(C4&"#Principal",RASTREADORES!$Y:$Y,0))&")","Sem rastreador principal")) -> Autotrac PRIME (Híbrido (satélite+4G)) | AS4: =IF(C4="","",IFERROR(INDEX(RASTREADORES!$H:$H,MATCH(C4&"#Principal",RASTREADORES!$Y:$Y,0)),"—")) -> 7715872 | AT4: =IF(C4="","",IFERROR(INDEX(RASTREADORES!$A:$A,MATCH(C4&"#Redundante",RASTREADORES!$Y:$Y,0)),IFERROR(INDEX(RASTREADORES!$A:$A,MATCH(C4&"#Isca retornável",RASTREADORES!$Y:$Y,0)),IFERROR(INDEX(RASTREADORES!$A:$A,MATCH(C4&"#Isca descartável",RASTREADORES!$Y:$Y,0)),"Nenhum")))) -> Nenhum | AU4: =IF(C4="","",IFERROR(INDEX(RASTREADORES!$L:$L,MATCH(C4&"#Principal",RASTREADORES!$Y:$Y,0)),"")) -> A confirmar | AV4: =IF(C4="","",IF(COUNTIFS(ESPELHAMENTOS!$B$2:$B$2000,C4,ESPELHAMENTOS!$O$2:$O$2000,"Sim")>0,"Sim","Não")) -> Sim | AW4: =IF(C4="","",COUNTIFS(ESPELHAMENTOS!$B$2:$B$2000,C4,ESPELHAMENTOS!$O$2:$O$2000,"Sim")) -> 1 | AX4: =IF(C4="","",IF(COUNTIFS(ESPELHAMENTOS!$B$2:$B$2000,C4,ESPELHAMENTOS!$O$2:$O$2000,"Sim",ESPELHAMENTOS!$E$2:$E$2000,"GR transportadora")>0,"Sim","Não")) -> Sim | AY4: =IF(OR(AQ4="",C4=""),"",IFERROR(ROUND((AQ4-SUMPRODUCT(MIN((ESPELHAMENTOS!$C$2:$C$2000=A4)*ESPELHAMENTOS!$H$2:$H$2000+(ESPELHAMENTOS!$C$2:$C$2000<>A4)*99999)))*24,1),"")) -> 4 | AZ4: =IF(C4="","",IF(COUNTIFS(CHECKLISTS!$B$2:$B$2000,C4,CHECKLISTS!$AH$2:$AH$2000,"Válido",CHECKLISTS!$AG$2:$AG$2000,">="&INT(IF(AO4="",TODAY(),AO4)))+COUNTIFS(CHECKLISTS!$B$2:$B$2000,C4,CHECKLISTS!$AH$2:$AH$2000,"Vence <=7d",CHECKLISTS!$AG$2:$AG$2000,">="&INT(IF(AO4="",TODAY(),AO4)))>0,"Sim","Não")) -> Sim | BA4: =IF(C4="","",IF(COUNTIFS(CHECKLISTS!$B$2:$B$2000,C4,CHECKLISTS!$AF$2:$AF$2000,"Aprovado")=0,"",SUMPRODUCT(MAX((CHECKLISTS!$B$2:$B$2000=C4)*CHECKLISTS!$AG$2:$AG$2000)))) | BB4: =IF(A4="","",IF(COUNTIFS(SMP!$B$2:$B$2000,A4,SMP!$I$2:$I$2000,"Liberada")+COUNTIFS(SMP!$B$2:$B$2000,A4,SMP!$I$2:$I$2000,"Em andamento")+COUNTIFS(SMP!$B$2:$B$2000,A4,SMP!$I$2:$I$2000,"Finalizada")>0,"Sim","Não")) -> Sim | BC4: =IF(A4="","",IFERROR(INDEX(SMP!$A:$A,MATCH(A4,SMP!$B:$B,0)),"—")) -> SMP-88240 | BD4: =IF(A4="","",IFERROR(INDEX(SMP!$I:$I,MATCH(A4,SMP!$B:$B,0)),"Não aberta")) -> Em andamento | BE4: =IF(A4="","",IFERROR(INDEX(SMP!$D:$D,MATCH(A4,SMP!$B:$B,0)),"")) -> A DEFINIR | BF4: =IF(A4="","",IF(COUNTIFS(AVERBACOES!$B$2:$B$2000,A4,AVERBACOES!$Q$2:$Q$2000,"Averbado completo")+COUNTIFS(AVERBACOES!$B$2:$B$2000,A4,AVERBACOES!$Q$2:$Q$2000,"Averbado CRT")+COUNTIFS(AVERBACOES!$B$2:$B$2000,A4,AVERBACOES!$Q$2:$Q$2000,"Averbado CT-e")+COUNTIFS(AVERBACOES!$B$2:$B$2000,A4,AVERBACOES!$Q$2:$Q$2000,"Averbado MDF-e")+COUNTIFS(AVERBACOES!$B$2:$B$2000,A4,AVERBACOES!$Q$2:$Q$2000,"Averbado pelo embarcador")>0,"Sim","Não")) -> Sim | BG4: =IF(A4="","",IFERROR(INDEX(AVERBACOES!$L:$L,MATCH(A4,AVERBACOES!$B:$B,0)),"—")) -> AV-2026-004530 | BH4: BR.1234.00459 | BI4: 2026BR000795 | BK4: Sim | BL4: 15 Fronteira liberada - trânsito exterior | BM4: =IF(BL4="",0,VALUE(LEFT(BL4,2))) -> 15 | BN4: =IF(A4="","",IF(AP4<>"","Sim","Não")) -> Sim | BO4: =IF(A4="","",IF(OR(BM4=8,BM4=9,BM4=10,BM4=11,BM4=15),"Sim","Não")) -> Sim | BP4: =IF(A4="","",IF(AND(BM4>=12,BM4<=14),"Sim","Não")) -> Não | BQ4: =IF(A4="","",IF(OR(AND(BM4>=16,BM4<=20),BR4<>""),"Sim","Não")) -> Não | BS4: =IF(A4="","",IF(OR(BM4=18,BM4=19,BM4=20),"Sim","Não")) -> Não | BT4: =IF(C4="","",IF(BV4=0,"Sem posição registrada",IFERROR(INDEX(POSICOES!$E:$E,MATCH(C4&"#"&ROUND(BV4*1440,0),POSICOES!$R:$R,0)),"?"))) -> RN127 km 210 | BU4: =IF(OR(C4="",BV4=0),"",IFERROR(INDEX(POSICOES!$F:$F,MATCH(C4&"#"&ROUND(BV4*1440,0),POSICOES!$R:$R,0))&"/"&INDEX(POSICOES!$G:$G,MATCH(C4&"#"&ROUND(BV4*1440,0),POSICOES!$R:$R,0))&" - "&INDEX(POSICOES!$H:$H,MATCH(C4&"#"&ROUND(BV4*1440,0),POSICOES!$R:$R,0)),"")) -> Federal/Entre Ríos - AR | BV4: =IF(C4="",0,SUMPRODUCT(MAX((POSICOES!$C$2:$C$3000=C4)*POSICOES!$B$2:$B$3000))) -> 46290.5 | BW4: =IF(OR(BV4=0,BM4=0,BM4>=20),"",ROUND((NOW()-BV4)*24,1)) -> 7.6 | BX4: =IF(BW4="","",IF(BW4<P_SINAL_ALERTA,"Online",IF(BW4<P_SINAL_CRIT,"Sem sinal 1-4h","Sem sinal >4h"))) -> Sem sinal >4h | BY4: 46292.75 | BZ4: 46293.833 | CA4: =IF(A4="","",IF(COUNTIFS(FRONTEIRA!$B$2:$B$2000,A4,FRONTEIRA!$AA$2:$AA$2000,"Sim")=0,"",ROUND(SUMIFS(FRONTEIRA!$Y$2:$Y$2000,FRONTEIRA!$B$2:$B$2000,A4,FRONTEIRA!$AA$2:$AA$2000,"Sim"),1))) | CB4: =IF(A4="","",IFERROR(INDEX(FRONTEIRA!$L:$L,MATCH(A4,FRONTEIRA!$B:$B,0)),"")) -> Verde | CC4: =IF(A4="","",IF(COUNTIFS(OCORRENCIAS!$B$2:$B$2000,A4,OCORRENCIAS!$Z$2:$Z$2000,"Sim")>0,"Sim","Não")) -> Sim | CD4: =IF(A4="","",IF(AND(N4="Sim",Q4="Sim",OR(U4="Sim",U4="N/A"),V4="Sim",M4<>"Inapto",AZ4="Sim",AV4="Sim",BB4="Sim",BF4="Sim",OR(BK4="Sim",BK4="N/A"),OR(T4="",AB4="",AB4<=T4),OR(AH4<>"Sim",CE4="Sim")),"APTO","BLOQUEADO")) -> APTO | CF4: =IF(N4<>"Sim","Motorista GR; ","")&IF(Q4<>"Sim","Motorista seguradora; ","")&IF(U4="Não","Motorista 2; ","")&IF(V4<>"Sim","Veículo GR; ","")&IF(M4="Inapto","Documentos do motorista; ","")&IF(AZ4<>"Sim","Checklist; ","")&IF(AV4<>"Sim","Espelhamento; ","")&IF(BB4<>"Sim","SMP; ","")&IF(BF4<>"Sim","Averbação; ","")&IF(BK4="Não","Docs internacionais; ","")&IF(AND(T4<>"",AB4<>"",AB4>T4),"Valor acima do perfil; ","")&IF(AND(AH4="Sim",CE4<>"Sim"),"Acima do LMG sem aprovação; ","") | CG4: =IF(A4="","",IF(CF4="","Nenhuma",LEFT(CF4,LEN(CF4)-2))) -> Nenhuma | CH4: =IF(A4="","",IF(AND(OR(BO4="Sim",BP4="Sim"),CD4="BLOQUEADO"),"Sim","Não")) -> Não | CI4: =IF(OR(C4="",BM4=0,BM4>=20),"Não",IF(B4=SUMPRODUCT(MAX((C$2:C$2000=C4)*(BM$2:BM$2000>0)*(BM$2:BM$2000<20)*B$2:B$2000)),"Sim","Não")) -> Sim | CJ4: =IF(A4="","","Viagem "&A4&" - Placa "&C4&" - "&BL4&" - Local: "&BT4&" - Motorista: "&I4&" (GR: "&N4&"; Seguradora: "&Q4&") - Rastreador: "&AR4&" no "&AS4&" - Espelhado: "&AV4&" - Checklist: "&AZ4&" - SMP: "&BB4&" - Averbado: "&BF4&" - Apto: "&CD4&" - Pendencias: "&CG4) -> Viagem RGB-2026-0415 - Placa IYD2E67 - 15 Fronteira liberada - trânsito exterior - Local: RN127 km 210 - Motorista: Luis Alberto Fagundes (GR: Sim; Seguradora: Sim) - Rastreador: Autotrac PRIME (Híbrido (satélite+4G)) no 7715872 - Espelhado: Sim - Checklist: Sim - SMP: Sim - Averbado: Sim - Apto: APTO - Pendencias: Nenhuma | CM4: Monitorar abertura do Cristo Redentor (risco neve). | CN4: 46290.573 | CO4: Analista GR 1 | CP4: =IF(OR(CN4="",BM4<7,BM4>=20),"",IF((NOW()-CN4)*24>P_ATUALIZ_MAX_H,"Sim","Não")) -> Sim
A5: RGB-2026-0418 | B5: 46289.458 | C5: JAK2E88 | D5: JBL9F12 | F5: =IF(C5="","",IFERROR(INDEX(VEICULOS!$C:$C,MATCH(C5,VEICULOS!$A:$A,0)),"?")&IF(D5="",""," + "&IFERROR(INDEX(VEICULOS!$C:$C,MATCH(D5,VEICULOS!$A:$A,0)),"?"))&IF(E5="",""," + "&IFERROR(INDEX(VEICULOS!$C:$C,MATCH(E5,VEICULOS!$A:$A,0)),"?"))) -> Cavalo 6x4 + Carreta Aberta 15m (100m3) | G5: =IF(C5="","",IFERROR(INDEX(VEICULOS!$I:$I,MATCH(C5,VEICULOS!$A:$A,0)),"Não cadastrado")) -> Agregado | H5: MOT-003 | I5: =IF(H5="","",IFERROR(INDEX(MOTORISTAS!$B:$B,MATCH(H5,MOTORISTAS!$A:$A,0)),"Não cadastrado")) -> Ricardo Alves Nunes | J5: Sim | L5: =IF(K5="","",IFERROR(INDEX(MOTORISTAS!$B:$B,MATCH(K5,MOTORISTAS!$A:$A,0)),"Não cadastrado")) | M5: =IF(H5="","",IFERROR(INDEX(MOTORISTAS!$AA:$AA,MATCH(H5,MOTORISTAS!$A:$A,0)),"Não cadastrado")) -> Inapto | N5: =IF(H5="","",IF(COUNTIFS(CONSULTAS!$C$2:$C$2000,H5,CONSULTAS!$E$2:$E$2000,"GR",CONSULTAS!$S$2:$S$2000,"Sim")>0,"Sim","Não")) -> Sim | O5: =IF(H5="","",IFERROR(INDEX(CONSULTAS!$L:$L,MATCH(H5&"#GR",CONSULTAS!$T:$T,0)),"—")) -> LIB-601277 | P5: =IF(H5="","",IFERROR(INDEX(CONSULTAS!$Q:$Q,MATCH(H5&"#GR",CONSULTAS!$T:$T,0)),"")) -> 46297 | Q5: =IF(H5="","",IF(COUNTIFS(CONSULTAS!$C$2:$C$2000,H5,CONSULTAS!$E$2:$E$2000,"Seguradora",CONSULTAS!$S$2:$S$2000,"Sim")>0,"Sim","Não")) -> Não | R5: =IF(H5="","",IFERROR(INDEX(CONSULTAS!$L:$L,MATCH(H5&"#Seguradora",CONSULTAS!$T:$T,0)),"—")) -> — | S5: =IF(H5="","",IFERROR(INDEX(CONSULTAS!$Q:$Q,MATCH(H5&"#Seguradora",CONSULTAS!$T:$T,0)),"")) | T5: =IF(H5="","",IFERROR(INDEX(CONSULTAS!$N:$N,MATCH(H5&"#GR",CONSULTAS!$T:$T,0)),"")) -> 500000 | U5: =IF(K5="","N/A",IF(AND(COUNTIFS(CONSULTAS!$C$2:$C$2000,K5,CONSULTAS!$E$2:$E$2000,"GR",CONSULTAS!$S$2:$S$2000,"Sim")>0,COUNTIFS(CONSULTAS!$C$2:$C$2000,K5,CONSULTAS!$E$2:$E$2000,"Seguradora",CONSULTAS!$S$2:$S$2000,"Sim")>0),"Sim","Não")) -> N/A | V5: =IF(C5="","",IFERROR(INDEX(VEICULOS!$X:$X,MATCH(C5,VEICULOS!$A:$A,0)),"Não")) -> Sim | W5: Embarcador AR/UY (exemplo) | X5: Embalagens plásticas | Y5: Carga seca geral | Z5: 310000 | AA5: BRL | AB5: =IF(Z5="","",IF(AA5="USD",Z5*P_TAXA_USD,Z5)) -> 310000 | AC5: =IF(OR(Y5="",AB5=""),0,SUMPRODUCT((PGR_REGRAS!$C$2:$C$61=Y5)*(PGR_REGRAS!$D$2:$D$61<=AB5)*(PGR_REGRAS!$E$2:$E$61>=AB5)*(PGR_REGRAS!$C$2:$C$61<>"")*ROW(PGR_REGRAS!$C$2:$C$61))) -> 3 | AD5: =IF(AC5=0,IF(Y5="","","Sem regra - consultar seguradora"),INDEX(PGR_REGRAS!$A:$A,AC5)) -> PGR-02 | AE5: =IF(AC5=0,"",INDEX(PGR_REGRAS!$T:$T,AC5)) -> Cadastro + rastreador 24h + espelhamento 2h antes; proibido terceiro (exemplo) | AF5: =IF(AC5=0,"",INDEX(PGR_REGRAS!$I:$I,AC5)) -> Não | AG5: =IF(AC5=0,"",INDEX(PGR_REGRAS!$K:$K,AC5)) -> 0 | AH5: =IF(AB5="","",IF(AB5>P_LMG_REF,"Sim","Não")) -> Não | AI5: Uruguaiana/RS/BR | AJ5: Montevidéu | AK5: UY | AM5: Barra do Quaraí-Bella Unión | AN5: Sim | AO5: 46290 | AP5: 46290.396 | AR5: =IF(C5="","",IFERROR(INDEX(RASTREADORES!$F:$F,MATCH(C5&"#Principal",RASTREADORES!$Y:$Y,0))&" ("&INDEX(RASTREADORES!$G:$G,MATCH(C5&"#Principal",RASTREADORES!$Y:$Y,0))&")","Sem rastreador principal")) -> Autotrac PRIME (Híbrido (satélite+4G)) | AS5: =IF(C5="","",IFERROR(INDEX(RASTREADORES!$H:$H,MATCH(C5&"#Principal",RASTREADORES!$Y:$Y,0)),"—")) -> 7719876 | AT5: =IF(C5="","",IFERROR(INDEX(RASTREADORES!$A:$A,MATCH(C5&"#Redundante",RASTREADORES!$Y:$Y,0)),IFERROR(INDEX(RASTREADORES!$A:$A,MATCH(C5&"#Isca retornável",RASTREADORES!$Y:$Y,0)),IFERROR(INDEX(RASTREADORES!$A:$A,MATCH(C5&"#Isca descartável",RASTREADORES!$Y:$Y,0)),"Nenhum")))) -> Nenhum | AU5: =IF(C5="","",IFERROR(INDEX(RASTREADORES!$L:$L,MATCH(C5&"#Principal",RASTREADORES!$Y:$Y,0)),"")) -> A confirmar | AV5: =IF(C5="","",IF(COUNTIFS(ESPELHAMENTOS!$B$2:$B$2000,C5,ESPELHAMENTOS!$O$2:$O$2000,"Sim")>0,"Sim","Não")) -> Não | AW5: =IF(C5="","",COUNTIFS(ESPELHAMENTOS!$B$2:$B$2000,C5,ESPELHAMENTOS!$O$2:$O$2000,"Sim")) -> 0 | AX5: =IF(C5="","",IF(COUNTIFS(ESPELHAMENTOS!$B$2:$B$2000,C5,ESPELHAMENTOS!$O$2:$O$2000,"Sim",ESPELHAMENTOS!$E$2:$E$2000,"GR transportadora")>0,"Sim","Não")) -> Não | AY5: =IF(OR(AQ5="",C5=""),"",IFERROR(ROUND((AQ5-SUMPRODUCT(MIN((ESPELHAMENTOS!$C$2:$C$2000=A5)*ESPELHAMENTOS!$H$2:$H$2000+(ESPELHAMENTOS!$C$2:$C$2000<>A5)*99999)))*24,1),"")) | AZ5: =IF(C5="","",IF(COUNTIFS(CHECKLISTS!$B$2:$B$2000,C5,CHECKLISTS!$AH$2:$AH$2000,"Válido",CHECKLISTS!$AG$2:$AG$2000,">="&INT(IF(AO5="",TODAY(),AO5)))+COUNTIFS(CHECKLISTS!$B$2:$B$2000,C5,CHECKLISTS!$AH$2:$AH$2000,"Vence <=7d",CHECKLISTS!$AG$2:$AG$2000,">="&INT(IF(AO5="",TODAY(),AO5)))>0,"Sim","Não")) -> Não | BA5: =IF(C5="","",IF(COUNTIFS(CHECKLISTS!$B$2:$B$2000,C5,CHECKLISTS!$AF$2:$AF$2000,"Aprovado")=0,"",SUMPRODUCT(MAX((CHECKLISTS!$B$2:$B$2000=C5)*CHECKLISTS!$AG$2:$AG$2000)))) | BB5: =IF(A5="","",IF(COUNTIFS(SMP!$B$2:$B$2000,A5,SMP!$I$2:$I$2000,"Liberada")+COUNTIFS(SMP!$B$2:$B$2000,A5,SMP!$I$2:$I$2000,"Em andamento")+COUNTIFS(SMP!$B$2:$B$2000,A5,SMP!$I$2:$I$2000,"Finalizada")>0,"Sim","Não")) -> Não | BC5: =IF(A5="","",IFERROR(INDEX(SMP!$A:$A,MATCH(A5,SMP!$B:$B,0)),"—")) -> — | BD5: =IF(A5="","",IFERROR(INDEX(SMP!$I:$I,MATCH(A5,SMP!$B:$B,0)),"Não aberta")) -> Não aberta | BE5: =IF(A5="","",IFERROR(INDEX(SMP!$D:$D,MATCH(A5,SMP!$B:$B,0)),"")) | BF5: =IF(A5="","",IF(COUNTIFS(AVERBACOES!$B$2:$B$2000,A5,AVERBACOES!$Q$2:$Q$2000,"Averbado completo")+COUNTIFS(AVERBACOES!$B$2:$B$2000,A5,AVERBACOES!$Q$2:$Q$2000,"Averbado CRT")+COUNTIFS(AVERBACOES!$B$2:$B$2000,A5,AVERBACOES!$Q$2:$Q$2000,"Averbado CT-e")+COUNTIFS(AVERBACOES!$B$2:$B$2000,A5,AVERBACOES!$Q$2:$Q$2000,"Averbado MDF-e")+COUNTIFS(AVERBACOES!$B$2:$B$2000,A5,AVERBACOES!$Q$2:$Q$2000,"Averbado pelo embarcador")>0,"Sim","Não")) -> Não | BG5: =IF(A5="","",IFERROR(INDEX(AVERBACOES!$L:$L,MATCH(A5,AVERBACOES!$B:$B,0)),"—")) -> 0 | BH5: BR.1234.00461 | BK5: Não | BL5: 06 Carregado - aguardando docs/SMP | BM5: =IF(BL5="",0,VALUE(LEFT(BL5,2))) -> 6 | BN5: =IF(A5="","",IF(AP5<>"","Sim","Não")) -> Sim | BO5: =IF(A5="","",IF(OR(BM5=8,BM5=9,BM5=10,BM5=11,BM5=15),"Sim","Não")) -> Não | BP5: =IF(A5="","",IF(AND(BM5>=12,BM5<=14),"Sim","Não")) -> Não | BQ5: =IF(A5="","",IF(OR(AND(BM5>=16,BM5<=20),BR5<>""),"Sim","Não")) -> Não | BS5: =IF(A5="","",IF(OR(BM5=18,BM5=19,BM5=20),"Sim","Não")) -> Não | BT5: =IF(C5="","",IF(BV5=0,"Sem posição registrada",IFERROR(INDEX(POSICOES!$E:$E,MATCH(C5&"#"&ROUND(BV5*1440,0),POSICOES!$R:$R,0)),"?"))) -> Sem posição registrada | BU5: =IF(OR(C5="",BV5=0),"",IFERROR(INDEX(POSICOES!$F:$F,MATCH(C5&"#"&ROUND(BV5*1440,0),POSICOES!$R:$R,0))&"/"&INDEX(POSICOES!$G:$G,MATCH(C5&"#"&ROUND(BV5*1440,0),POSICOES!$R:$R,0))&" - "&INDEX(POSICOES!$H:$H,MATCH(C5&"#"&ROUND(BV5*1440,0),POSICOES!$R:$R,0)),"")) | BV5: =IF(C5="",0,SUMPRODUCT(MAX((POSICOES!$C$2:$C$3000=C5)*POSICOES!$B$2:$B$3000))) -> 0 | BW5: =IF(OR(BV5=0,BM5=0,BM5>=20),"",ROUND((NOW()-BV5)*24,1)) | BX5: =IF(BW5="","",IF(BW5<P_SINAL_ALERTA,"Online",IF(BW5<P_SINAL_CRIT,"Sem sinal 1-4h","Sem sinal >4h"))) | BZ5: 46291.833 | CA5: =IF(A5="","",IF(COUNTIFS(FRONTEIRA!$B$2:$B$2000,A5,FRONTEIRA!$AA$2:$AA$2000,"Sim")=0,"",ROUND(SUMIFS(FRONTEIRA!$Y$2:$Y$2000,FRONTEIRA!$B$2:$B$2000,A5,FRONTEIRA!$AA$2:$AA$2000,"Sim"),1))) | CB5: =IF(A5="","",IFERROR(INDEX(FRONTEIRA!$L:$L,MATCH(A5,FRONTEIRA!$B:$B,0)),"")) | CC5: =IF(A5="","",IF(COUNTIFS(OCORRENCIAS!$B$2:$B$2000,A5,OCORRENCIAS!$Z$2:$Z$2000,"Sim")>0,"Sim","Não")) -> Não | CD5: =IF(A5="","",IF(AND(N5="Sim",Q5="Sim",OR(U5="Sim",U5="N/A"),V5="Sim",M5<>"Inapto",AZ5="Sim",AV5="Sim",BB5="Sim",BF5="Sim",OR(BK5="Sim",BK5="N/A"),OR(T5="",AB5="",AB5<=T5),OR(AH5<>"Sim",CE5="Sim")),"APTO","BLOQUEADO")) -> BLOQUEADO | CF5: =IF(N5<>"Sim","Motorista GR; ","")&IF(Q5<>"Sim","Motorista seguradora; ","")&IF(U5="Não","Motorista 2; ","")&IF(V5<>"Sim","Veículo GR; ","")&IF(M5="Inapto","Documentos do motorista; ","")&IF(AZ5<>"Sim","Checklist; ","")&IF(AV5<>"Sim","Espelhamento; ","")&IF(BB5<>"Sim","SMP; ","")&IF(BF5<>"Sim","Averbação; ","")&IF(BK5="Não","Docs internacionais; ","")&IF(AND(T5<>"",AB5<>"",AB5>T5),"Valor acima do perfil; ","")&IF(AND(AH5="Sim",CE5<>"Sim"),"Acima do LMG sem aprovação; ","") -> Motorista seguradora; Documentos do motorista; Checklist; Espelhamento; SMP; Averbação; Docs internacionais; | CG5: =IF(A5="","",IF(CF5="","Nenhuma",LEFT(CF5,LEN(CF5)-2))) -> Motorista seguradora; Documentos do motorista; Checklist; Espelhamento; SMP; Averbação; Docs internacionais | CH5: =IF(A5="","",IF(AND(OR(BO5="Sim",BP5="Sim"),CD5="BLOQUEADO"),"Sim","Não")) -> Não | CI5: =IF(OR(C5="",BM5=0,BM5>=20),"Não",IF(B5=SUMPRODUCT(MAX((C$2:C$2000=C5)*(BM$2:BM$2000>0)*(BM$2:BM$2000<20)*B$2:B$2000)),"Sim","Não")) -> Sim | CJ5: =IF(A5="","","Viagem "&A5&" - Placa "&C5&" - "&BL5&" - Local: "&BT5&" - Motorista: "&I5&" (GR: "&N5&"; Seguradora: "&Q5&") - Rastreador: "&AR5&" no "&AS5&" - Espelhado: "&AV5&" - Checklist: "&AZ5&" - SMP: "&BB5&" - Averbado: "&BF5&" - Apto: "&CD5&" - Pendencias: "&CG5) -> Viagem RGB-2026-0418 - Placa JAK2E88 - 06 Carregado - aguardando docs/SMP - Local: Sem posição registrada - Motorista: Ricardo Alves Nunes (GR: Sim; Seguradora: Não) - Rastreador: Autotrac PRIME (Híbrido (satélite+4G)) no 7719876 - Espelhado: Não - Checklist: Não - SMP: Não - Averbado: Não - Apto: BLOQUEADO - Pendencias: Motorista seguradora; Documentos do motorista; Checklist; Espelhamento; SMP; Averbação; Docs internacionais | CM5: Refazer checklist do sensor sider antes de abrir a SMP. | CN5: 46290.479 | CO5: Analista GR 2 | CP5: =IF(OR(CN5="",BM5<7,BM5>=20),"",IF((NOW()-CN5)*24>P_ATUALIZ_MAX_H,"Sim","Não"))
A6: RGB-2026-0421 | B6: 46290.375 | C6: IYB5C34 | D6: IRS8H05 | F6: =IF(C6="","",IFERROR(INDEX(VEICULOS!$C:$C,MATCH(C6,VEICULOS!$A:$A,0)),"?")&IF(D6="",""," + "&IFERROR(INDEX(VEICULOS!$C:$C,MATCH(D6,VEICULOS!$A:$A,0)),"?"))&IF(E6="",""," + "&IFERROR(INDEX(VEICULOS!$C:$C,MATCH(E6,VEICULOS!$A:$A,0)),"?"))) -> Cavalo 6x4 + Carreta Sider 15,45m (107m3) | G6: =IF(C6="","",IFERROR(INDEX(VEICULOS!$I:$I,MATCH(C6,VEICULOS!$A:$A,0)),"Não cadastrado")) -> Frota própria (CLT) | H6: MOT-004 | I6: =IF(H6="","",IFERROR(INDEX(MOTORISTAS!$B:$B,MATCH(H6,MOTORISTAS!$A:$A,0)),"Não cadastrado")) -> Marcelo Duarte Lima | J6: Não | L6: =IF(K6="","",IFERROR(INDEX(MOTORISTAS!$B:$B,MATCH(K6,MOTORISTAS!$A:$A,0)),"Não cadastrado")) | M6: =IF(H6="","",IFERROR(INDEX(MOTORISTAS!$AA:$AA,MATCH(H6,MOTORISTAS!$A:$A,0)),"Não cadastrado")) -> Inapto | N6: =IF(H6="","",IF(COUNTIFS(CONSULTAS!$C$2:$C$2000,H6,CONSULTAS!$E$2:$E$2000,"GR",CONSULTAS!$S$2:$S$2000,"Sim")>0,"Sim","Não")) -> Não | O6: =IF(H6="","",IFERROR(INDEX(CONSULTAS!$L:$L,MATCH(H6&"#GR",CONSULTAS!$T:$T,0)),"—")) -> — | P6: =IF(H6="","",IFERROR(INDEX(CONSULTAS!$Q:$Q,MATCH(H6&"#GR",CONSULTAS!$T:$T,0)),"")) | Q6: =IF(H6="","",IF(COUNTIFS(CONSULTAS!$C$2:$C$2000,H6,CONSULTAS!$E$2:$E$2000,"Seguradora",CONSULTAS!$S$2:$S$2000,"Sim")>0,"Sim","Não")) -> Não | R6: =IF(H6="","",IFERROR(INDEX(CONSULTAS!$L:$L,MATCH(H6&"#Seguradora",CONSULTAS!$T:$T,0)),"—")) -> — | S6: =IF(H6="","",IFERROR(INDEX(CONSULTAS!$Q:$Q,MATCH(H6&"#Seguradora",CONSULTAS!$T:$T,0)),"")) | T6: =IF(H6="","",IFERROR(INDEX(CONSULTAS!$N:$N,MATCH(H6&"#GR",CONSULTAS!$T:$T,0)),"")) | U6: =IF(K6="","N/A",IF(AND(COUNTIFS(CONSULTAS!$C$2:$C$2000,K6,CONSULTAS!$E$2:$E$2000,"GR",CONSULTAS!$S$2:$S$2000,"Sim")>0,COUNTIFS(CONSULTAS!$C$2:$C$2000,K6,CONSULTAS!$E$2:$E$2000,"Seguradora",CONSULTAS!$S$2:$S$2000,"Sim")>0),"Sim","Não")) -> N/A | V6: =IF(C6="","",IFERROR(INDEX(VEICULOS!$X:$X,MATCH(C6,VEICULOS!$A:$A,0)),"Não")) -> Sim | W6: Cliente Exemplo PY | X6: Autopeças | Y6: Autopeças | Z6: 240000 | AA6: BRL | AB6: =IF(Z6="","",IF(AA6="USD",Z6*P_TAXA_USD,Z6)) -> 240000 | AC6: =IF(OR(Y6="",AB6=""),0,SUMPRODUCT((PGR_REGRAS!$C$2:$C$61=Y6)*(PGR_REGRAS!$D$2:$D$61<=AB6)*(PGR_REGRAS!$E$2:$E$61>=AB6)*(PGR_REGRAS!$C$2:$C$61<>"")*ROW(PGR_REGRAS!$C$2:$C$61))) -> 6 | AD6: =IF(AC6=0,IF(Y6="","","Sem regra - consultar seguradora"),INDEX(PGR_REGRAS!$A:$A,AC6)) -> PGR-05 | AE6: =IF(AC6=0,"",INDEX(PGR_REGRAS!$T:$T,AC6)) -> Cadastro + rastreador (exemplo) | AF6: =IF(AC6=0,"",INDEX(PGR_REGRAS!$I:$I,AC6)) -> Não | AG6: =IF(AC6=0,"",INDEX(PGR_REGRAS!$K:$K,AC6)) -> 0 | AH6: =IF(AB6="","",IF(AB6>P_LMG_REF,"Sim","Não")) -> Não | AI6: Uruguaiana/RS/BR | AJ6: Assunción | AK6: PY | AL6: AR | AM6: Posadas-Encarnación (AR-PY) | AO6: 46291 | AR6: =IF(C6="","",IFERROR(INDEX(RASTREADORES!$F:$F,MATCH(C6&"#Principal",RASTREADORES!$Y:$Y,0))&" ("&INDEX(RASTREADORES!$G:$G,MATCH(C6&"#Principal",RASTREADORES!$Y:$Y,0))&")","Sem rastreador principal")) -> Autotrac PRIME (Híbrido (satélite+4G)) | AS6: =IF(C6="","",IFERROR(INDEX(RASTREADORES!$H:$H,MATCH(C6&"#Principal",RASTREADORES!$Y:$Y,0)),"—")) -> 7714410 | AT6: =IF(C6="","",IFERROR(INDEX(RASTREADORES!$A:$A,MATCH(C6&"#Redundante",RASTREADORES!$Y:$Y,0)),IFERROR(INDEX(RASTREADORES!$A:$A,MATCH(C6&"#Isca retornável",RASTREADORES!$Y:$Y,0)),IFERROR(INDEX(RASTREADORES!$A:$A,MATCH(C6&"#Isca descartável",RASTREADORES!$Y:$Y,0)),"Nenhum")))) -> Nenhum | AU6: =IF(C6="","",IFERROR(INDEX(RASTREADORES!$L:$L,MATCH(C6&"#Principal",RASTREADORES!$Y:$Y,0)),"")) -> A confirmar | AV6: =IF(C6="","",IF(COUNTIFS(ESPELHAMENTOS!$B$2:$B$2000,C6,ESPELHAMENTOS!$O$2:$O$2000,"Sim")>0,"Sim","Não")) -> Não | AW6: =IF(C6="","",COUNTIFS(ESPELHAMENTOS!$B$2:$B$2000,C6,ESPELHAMENTOS!$O$2:$O$2000,"Sim")) -> 0 | AX6: =IF(C6="","",IF(COUNTIFS(ESPELHAMENTOS!$B$2:$B$2000,C6,ESPELHAMENTOS!$O$2:$O$2000,"Sim",ESPELHAMENTOS!$E$2:$E$2000,"GR transportadora")>0,"Sim","Não")) -> Não | AY6: =IF(OR(AQ6="",C6=""),"",IFERROR(ROUND((AQ6-SUMPRODUCT(MIN((ESPELHAMENTOS!$C$2:$C$2000=A6)*ESPELHAMENTOS!$H$2:$H$2000+(ESPELHAMENTOS!$C$2:$C$2000<>A6)*99999)))*24,1),"")) | AZ6: =IF(C6="","",IF(COUNTIFS(CHECKLISTS!$B$2:$B$2000,C6,CHECKLISTS!$AH$2:$AH$2000,"Válido",CHECKLISTS!$AG$2:$AG$2000,">="&INT(IF(AO6="",TODAY(),AO6)))+COUNTIFS(CHECKLISTS!$B$2:$B$2000,C6,CHECKLISTS!$AH$2:$AH$2000,"Vence <=7d",CHECKLISTS!$AG$2:$AG$2000,">="&INT(IF(AO6="",TODAY(),AO6)))>0,"Sim","Não")) -> Sim | BA6: =IF(C6="","",IF(COUNTIFS(CHECKLISTS!$B$2:$B$2000,C6,CHECKLISTS!$AF$2:$AF$2000,"Aprovado")=0,"",SUMPRODUCT(MAX((CHECKLISTS!$B$2:$B$2000=C6)*CHECKLISTS!$AG$2:$AG$2000)))) | BB6: =IF(A6="","",IF(COUNTIFS(SMP!$B$2:$B$2000,A6,SMP!$I$2:$I$2000,"Liberada")+COUNTIFS(SMP!$B$2:$B$2000,A6,SMP!$I$2:$I$2000,"Em andamento")+COUNTIFS(SMP!$B$2:$B$2000,A6,SMP!$I$2:$I$2000,"Finalizada")>0,"Sim","Não")) -> Não | BC6: =IF(A6="","",IFERROR(INDEX(SMP!$A:$A,MATCH(A6,SMP!$B:$B,0)),"—")) -> — | BD6: =IF(A6="","",IFERROR(INDEX(SMP!$I:$I,MATCH(A6,SMP!$B:$B,0)),"Não aberta")) -> Não aberta | BE6: =IF(A6="","",IFERROR(INDEX(SMP!$D:$D,MATCH(A6,SMP!$B:$B,0)),"")) | BF6: =IF(A6="","",IF(COUNTIFS(AVERBACOES!$B$2:$B$2000,A6,AVERBACOES!$Q$2:$Q$2000,"Averbado completo")+COUNTIFS(AVERBACOES!$B$2:$B$2000,A6,AVERBACOES!$Q$2:$Q$2000,"Averbado CRT")+COUNTIFS(AVERBACOES!$B$2:$B$2000,A6,AVERBACOES!$Q$2:$Q$2000,"Averbado CT-e")+COUNTIFS(AVERBACOES!$B$2:$B$2000,A6,AVERBACOES!$Q$2:$Q$2000,"Averbado MDF-e")+COUNTIFS(AVERBACOES!$B$2:$B$2000,A6,AVERBACOES!$Q$2:$Q$2000,"Averbado pelo embarcador")>0,"Sim","Não")) -> Não | BG6: =IF(A6="","",IFERROR(INDEX(AVERBACOES!$L:$L,MATCH(A6,AVERBACOES!$B:$B,0)),"—")) -> — | BL6: 02 Aguardando liberação GR | BM6: =IF(BL6="",0,VALUE(LEFT(BL6,2))) -> 2 | BN6: =IF(A6="","",IF(AP6<>"","Sim","Não")) -> Não | BO6: =IF(A6="","",IF(OR(BM6=8,BM6=9,BM6=10,BM6=11,BM6=15),"Sim","Não")) -> Não | BP6: =IF(A6="","",IF(AND(BM6>=12,BM6<=14),"Sim","Não")) -> Não | BQ6: =IF(A6="","",IF(OR(AND(BM6>=16,BM6<=20),BR6<>""),"Sim","Não")) -> Não | BS6: =IF(A6="","",IF(OR(BM6=18,BM6=19,BM6=20),"Sim","Não")) -> Não | BT6: =IF(C6="","",IF(BV6=0,"Sem posição registrada",IFERROR(INDEX(POSICOES!$E:$E,MATCH(C6&"#"&ROUND(BV6*1440,0),POSICOES!$R:$R,0)),"?"))) -> Depósito destino - Rosario | BU6: =IF(OR(C6="",BV6=0),"",IFERROR(INDEX(POSICOES!$F:$F,MATCH(C6&"#"&ROUND(BV6*1440,0),POSICOES!$R:$R,0))&"/"&INDEX(POSICOES!$G:$G,MATCH(C6&"#"&ROUND(BV6*1440,0),POSICOES!$R:$R,0))&" - "&INDEX(POSICOES!$H:$H,MATCH(C6&"#"&ROUND(BV6*1440,0),POSICOES!$R:$R,0)),"")) -> Rosario/Santa Fe - AR | BV6: =IF(C6="",0,SUMPRODUCT(MAX((POSICOES!$C$2:$C$3000=C6)*POSICOES!$B$2:$B$3000))) -> 46290.333 | BW6: =IF(OR(BV6=0,BM6=0,BM6>=20),"",ROUND((NOW()-BV6)*24,1)) -> 11.6 | BX6: =IF(BW6="","",IF(BW6<P_SINAL_ALERTA,"Online",IF(BW6<P_SINAL_CRIT,"Sem sinal 1-4h","Sem sinal >4h"))) -> Sem sinal >4h | CA6: =IF(A6="","",IF(COUNTIFS(FRONTEIRA!$B$2:$B$2000,A6,FRONTEIRA!$AA$2:$AA$2000,"Sim")=0,"",ROUND(SUMIFS(FRONTEIRA!$Y$2:$Y$2000,FRONTEIRA!$B$2:$B$2000,A6,FRONTEIRA!$AA$2:$AA$2000,"Sim"),1))) | CB6: =IF(A6="","",IFERROR(INDEX(FRONTEIRA!$L:$L,MATCH(A6,FRONTEIRA!$B:$B,0)),"")) | CC6: =IF(A6="","",IF(COUNTIFS(OCORRENCIAS!$B$2:$B$2000,A6,OCORRENCIAS!$Z$2:$Z$2000,"Sim")>0,"Sim","Não")) -> Não | CD6: =IF(A6="","",IF(AND(N6="Sim",Q6="Sim",OR(U6="Sim",U6="N/A"),V6="Sim",M6<>"Inapto",AZ6="Sim",AV6="Sim",BB6="Sim",BF6="Sim",OR(BK6="Sim",BK6="N/A"),OR(T6="",AB6="",AB6<=T6),OR(AH6<>"Sim",CE6="Sim")),"APTO","BLOQUEADO")) -> BLOQUEADO | CF6: =IF(N6<>"Sim","Motorista GR; ","")&IF(Q6<>"Sim","Motorista seguradora; ","")&IF(U6="Não","Motorista 2; ","")&IF(V6<>"Sim","Veículo GR; ","")&IF(M6="Inapto","Documentos do motorista; ","")&IF(AZ6<>"Sim","Checklist; ","")&IF(AV6<>"Sim","Espelhamento; ","")&IF(BB6<>"Sim","SMP; ","")&IF(BF6<>"Sim","Averbação; ","")&IF(BK6="Não","Docs internacionais; ","")&IF(AND(T6<>"",AB6<>"",AB6>T6),"Valor acima do perfil; ","")&IF(AND(AH6="Sim",CE6<>"Sim"),"Acima do LMG sem aprovação; ","") -> Motorista GR; Motorista seguradora; Documentos do motorista; Espelhamento; SMP; Averbação; | CG6: =IF(A6="","",IF(CF6="","Nenhuma",LEFT(CF6,LEN(CF6)-2))) -> Motorista GR; Motorista seguradora; Documentos do motorista; Espelhamento; SMP; Averbação | CH6: =IF(A6="","",IF(AND(OR(BO6="Sim",BP6="Sim"),CD6="BLOQUEADO"),"Sim","Não")) -> Não | CI6: =IF(OR(C6="",BM6=0,BM6>=20),"Não",IF(B6=SUMPRODUCT(MAX((C$2:C$2000=C6)*(BM$2:BM$2000>0)*(BM$2:BM$2000<20)*B$2:B$2000)),"Sim","Não")) -> Sim | CJ6: =IF(A6="","","Viagem "&A6&" - Placa "&C6&" - "&BL6&" - Local: "&BT6&" - Motorista: "&I6&" (GR: "&N6&"; Seguradora: "&Q6&") - Rastreador: "&AR6&" no "&AS6&" - Espelhado: "&AV6&" - Checklist: "&AZ6&" - SMP: "&BB6&" - Averbado: "&BF6&" - Apto: "&CD6&" - Pendencias: "&CG6) -> Viagem RGB-2026-0421 - Placa IYB5C34 - 02 Aguardando liberação GR - Local: Depósito destino - Rosario - Motorista: Marcelo Duarte Lima (GR: Não; Seguradora: Não) - Rastreador: Autotrac PRIME (Híbrido (satélite+4G)) no 7714410 - Espelhado: Não - Checklist: Sim - SMP: Não - Averbado: Não - Apto: BLOQUEADO - Pendencias: Motorista GR; Motorista seguradora; Documentos do motorista; Espelhamento; SMP; Averbação | CM6: Trocar motorista ou regularizar toxicológico e consulta antes de liberar. | CN6: 46290.417 | CO6: Analista GR 2 | CP6: =IF(OR(CN6="",BM6<7,BM6>=20),"",IF((NOW()-CN6)*24>P_ATUALIZ_MAX_H,"Sim","Não"))
